2024-05-17 23:13:50,744 INFO    StreamThr :1443581 [internal.py:wandb_internal():85] W&B internal server running at pid: 1443581, started at: 2024-05-17 23:13:50.732494
2024-05-17 23:13:50,750 DEBUG   HandlerThread:1443581 [handler.py:handle_request():158] handle_request: status
2024-05-17 23:13:50,766 INFO    WriterThread:1443581 [datastore.py:open_for_write():87] open: /nlsasfs/home/ai4bharat/praveens/srija/assignment_1/wandb/run-20240517_231350-axl0xjp0/run-axl0xjp0.wandb
2024-05-17 23:13:50,767 DEBUG   SenderThread:1443581 [sender.py:send():378] send: header
2024-05-17 23:13:50,771 DEBUG   SenderThread:1443581 [sender.py:send():378] send: run
2024-05-17 23:13:51,362 ERROR   SenderThread:1443581 [internal_api.py:execute():344] 403 response executing GraphQL.
2024-05-17 23:13:51,362 ERROR   SenderThread:1443581 [internal_api.py:execute():345] {"errors":[{"message":"permission denied","path":["upsertBucket"],"extensions":{"code":"PERMISSION_ERROR"}}],"data":{"upsertBucket":null}}
2024-05-17 23:13:51,362 ERROR   SenderThread:1443581 [sender.py:send_run():970] It appears that you do not have permission to access the requested resource. Please reach out to the project owner to grant you access. If you have the correct permissions, verify that there are no issues with your networking setup.(Error 403: Forbidden)
Traceback (most recent call last):
  File "/nlsasfs/home/ai4bharat/praveens/miniconda3/envs/dl_as/lib/python3.10/site-packages/wandb/sdk/lib/retry.py", line 131, in __call__
    result = self._call_fn(*args, **kwargs)
  File "/nlsasfs/home/ai4bharat/praveens/miniconda3/envs/dl_as/lib/python3.10/site-packages/wandb/sdk/internal/internal_api.py", line 340, in execute
    return self.client.execute(*args, **kwargs)  # type: ignore
  File "/nlsasfs/home/ai4bharat/praveens/miniconda3/envs/dl_as/lib/python3.10/site-packages/wandb/vendor/gql-0.2.0/wandb_gql/client.py", line 52, in execute
    result = self._get_result(document, *args, **kwargs)
  File "/nlsasfs/home/ai4bharat/praveens/miniconda3/envs/dl_as/lib/python3.10/site-packages/wandb/vendor/gql-0.2.0/wandb_gql/client.py", line 60, in _get_result
    return self.transport.execute(document, *args, **kwargs)
  File "/nlsasfs/home/ai4bharat/praveens/miniconda3/envs/dl_as/lib/python3.10/site-packages/wandb/sdk/lib/gql_request.py", line 59, in execute
    request.raise_for_status()
  File "/nlsasfs/home/ai4bharat/praveens/miniconda3/envs/dl_as/lib/python3.10/site-packages/requests/models.py", line 1021, in raise_for_status
    raise HTTPError(http_error_msg, response=self)
requests.exceptions.HTTPError: 403 Client Error: Forbidden for url: https://api.wandb.ai/graphql

During handling of the above exception, another exception occurred:

Traceback (most recent call last):
  File "/nlsasfs/home/ai4bharat/praveens/miniconda3/envs/dl_as/lib/python3.10/site-packages/wandb/sdk/internal/sender.py", line 968, in send_run
    server_run = self._init_run(run, config_value_dict)
  File "/nlsasfs/home/ai4bharat/praveens/miniconda3/envs/dl_as/lib/python3.10/site-packages/wandb/sdk/internal/sender.py", line 1013, in _init_run
    server_run, inserted, server_messages = self._api.upsert_run(
  File "/nlsasfs/home/ai4bharat/praveens/miniconda3/envs/dl_as/lib/python3.10/site-packages/wandb/apis/normalize.py", line 73, in wrapper
    raise err
  File "/nlsasfs/home/ai4bharat/praveens/miniconda3/envs/dl_as/lib/python3.10/site-packages/wandb/apis/normalize.py", line 41, in wrapper
    return func(*args, **kwargs)
  File "/nlsasfs/home/ai4bharat/praveens/miniconda3/envs/dl_as/lib/python3.10/site-packages/wandb/sdk/internal/internal_api.py", line 2188, in upsert_run
    response = self.gql(
  File "/nlsasfs/home/ai4bharat/praveens/miniconda3/envs/dl_as/lib/python3.10/site-packages/wandb/sdk/internal/internal_api.py", line 312, in gql
    ret = self._retry_gql(
  File "/nlsasfs/home/ai4bharat/praveens/miniconda3/envs/dl_as/lib/python3.10/site-packages/wandb/sdk/lib/retry.py", line 147, in __call__
    retry_timedelta_triggered = check_retry_fn(e)
  File "/nlsasfs/home/ai4bharat/praveens/miniconda3/envs/dl_as/lib/python3.10/site-packages/wandb/util.py", line 965, in check_retry_fn
    return fallback_retry_fn(e)
  File "/nlsasfs/home/ai4bharat/praveens/miniconda3/envs/dl_as/lib/python3.10/site-packages/wandb/util.py", line 907, in no_retry_auth
    raise CommError(
wandb.errors.CommError: It appears that you do not have permission to access the requested resource. Please reach out to the project owner to grant you access. If you have the correct permissions, verify that there are no issues with your networking setup.(Error 403: Forbidden)
2024-05-17 23:13:51,406 DEBUG   HandlerThread:1443581 [handler.py:handle_request():158] handle_request: shutdown
2024-05-17 23:13:51,406 INFO    HandlerThread:1443581 [handler.py:finish():882] shutting down handler
2024-05-17 23:13:51,771 INFO    WriterThread:1443581 [datastore.py:close():296] close: /nlsasfs/home/ai4bharat/praveens/srija/assignment_1/wandb/run-20240517_231350-axl0xjp0/run-axl0xjp0.wandb
2024-05-17 23:13:52,378 INFO    SenderThread:1443581 [sender.py:finish():1545] shutting down sender
